<?xml version="1.0"?>
<!--
  lwa4p_robotnik.urdf.xacro 
  
  Schunk LWA 4P modified by Robotnik Automation
-->

<robot xmlns:xacro="http://www.ros.org/wiki/xacro">

  <xacro:macro name="lwa4p_robotnik">

    <joint name="guardian_powerball_joint" type="fixed">
      <origin xyz="0.15 0 0.378" rpy="0 0 0" />
      <parent link="base_link" />
      <child link="powerball_base_link"/>
    </joint>
    <link name="powerball_base_link">
      <inertial>
        <mass value="0.01" />
        <origin xyz="0 0 0" />
        <inertia ixx="0.001"  ixy="0.0"  ixz="0.0"
                 iyy="0.001"  iyz="0.0"
                 izz="0.001" />
      </inertial>
      <visual>
        <origin xyz="0 0 0" rpy="0 0 0"/>
        <geometry>
          <cylinder length="0.01" radius="0.1"/>
        </geometry>
      </visual>
      <collision>
        <origin xyz="0 0 0" rpy="0 0 0"/>
        <geometry>
          <cylinder length="0.01" radius="0.1"/>
        </geometry>
      </collision>
    </link>
  
    <gazebo reference="powerball_base_link">
      <material>Gazebo/FlatBlack</material>
      <turnGravityOff>false</turnGravityOff>
    </gazebo>
    
    
    <!-- arm -->
    <joint name="arm_0_joint" type="fixed">
      <origin rpy="3.1415926 0 0" xyz="0 0 0.005"/>
      <parent link="powerball_base_link"/>
      <child link="arm_0_link"/>
    </joint>
    <link name="arm_0_link">
      <inertial>
        <origin rpy="0 0 0" xyz="0 0 0"/>
        <mass value="0.29364"/>
        <inertia ixx="0.01" ixy="0" ixz="0" iyy="0.01" iyz="0" izz="0.01"/>
      </inertial>
      <visual>
        <origin rpy="0 0 0" xyz="0 0 0"/>
        <geometry>
          <mesh filename="package://g_ball_description/meshes/lwa4p_robotnik/powerball0.stl"/>
        </geometry>
      </visual>
      <collision>
        <origin rpy="0 0 0" xyz="0 0 0"/>
        <geometry>
          <mesh filename="package://g_ball_description/meshes/lwa4p_robotnik/powerball0.stl"/>
        </geometry>
      </collision>
    </link>
    <joint name="arm_1_joint" type="revolute">
      <origin rpy="0 0 0" xyz="0 0 -0.0897"/>
      <parent link="arm_0_link"/>
      <child link="arm_1_link"/>
      <axis xyz="0 0 -1"/>
      <calibration rising="0"/>
      <dynamics damping="10"/>
      <!--limit effort="370" lower="-6.2831853" upper="6.2831853" velocity="2.0"/-->
      <limit effort="370" lower="-2.97" upper="2.97" velocity="2.0"/>
      <safety_controller k_position="20" k_velocity="50" soft_lower_limit="-6.2731853" soft_upper_limit="6.2731853"/>
    </joint>
    <link name="arm_1_link">
      <inertial>
        <origin rpy="0 0 0" xyz="0 0 0"/>
        <mass value="0.29364"/>
        <inertia ixx="0.01" ixy="0" ixz="0" iyy="0.01" iyz="0" izz="0.01"/>
      </inertial>
      <visual>
        <origin rpy="0 0 0" xyz="0 0 0"/>
        <geometry>
          <mesh filename="package://g_ball_description/meshes/lwa4p_robotnik/powerball1.stl"/>
        </geometry>
        <material name="grey">
    <color rgba="0.5 0.5 0.5 1"/>
        </material>
      </visual>
      <collision>
        <origin rpy="0 0 0" xyz="0 0 0"/>
        <geometry>
          <mesh filename="package://g_ball_description/meshes/lwa4p_robotnik/powerball1.stl"/>
        </geometry>
      </collision>
    </link>
    <joint name="arm_2_joint" type="revolute">
      <origin rpy="1.5708 0 0" xyz="0 0 0"/>
      <parent link="arm_1_link"/>
      <child link="arm_2_link"/>
      <axis xyz="0 0 -1"/>
      <calibration rising="0"/>
      <dynamics damping="10"/>
      <!--limit effort="370" lower="-2.0943951" upper="2.0943951" velocity="2.0"/-->
      <limit effort="370" lower="-1.92" upper="1.92" velocity="2.0"/>
      <safety_controller k_position="20" k_velocity="50" soft_lower_limit="-2.0843" soft_upper_limit="2.0843"/>
    </joint>
    <link name="arm_2_link">
      <inertial>
        <origin rpy="0 0 0" xyz="0 0 0"/>
        <mass value="1.68311"/>
        <inertia ixx="0.03" ixy="0" ixz="0" iyy="0.03" iyz="0" izz="0.03"/>
      </inertial>
      <visual>
        <origin rpy="0 0 0" xyz="0 0 0"/>
        <geometry>
          <mesh filename="package://g_ball_description/meshes/lwa4p_robotnik/powerball2_robotnik.stl"/>
        </geometry>
      </visual>
      <collision>
        <origin rpy="0 0 0" xyz="0 0 0"/>
        <geometry>
          <mesh filename="package://g_ball_description/meshes/lwa4p_robotnik/powerball2_robotnik.stl"/>
        </geometry>
      </collision>
    </link>
    <joint name="arm_3_joint" type="revolute">
      <!--origin rpy="3.14159 0 0" xyz="0 -0.350 0"/-->
      <origin rpy="3.14159 0 0" xyz="0 -0.500 0"/>
      <parent link="arm_2_link"/>
      <child link="arm_3_link"/>
      <axis xyz="0 0 -1"/>
      <calibration rising="0"/>
      <dynamics damping="5"/>
      <!--limit effort="176" lower="-6.2831853" upper="6.2831853" velocity="2.0"/-->
      <limit effort="176" lower="-2.71" upper="2.71" velocity="2.0"/>
      <safety_controller k_position="20" k_velocity="25" soft_lower_limit="-6.2731853" soft_upper_limit="6.2731853"/>
    </joint>
    <link name="arm_3_link">
      <inertial>
        <origin rpy="0 0 0" xyz="0 0 0"/>
        <mass value="2.1"/>
        <inertia ixx="0.03" ixy="0" ixz="0" iyy="0.03" iyz="0" izz="0.03"/>
      </inertial>
      <visual>
        <origin rpy="0 0 0" xyz="0 0 0"/>
        <geometry>
          <mesh filename="package://g_ball_description/meshes/lwa4p_robotnik/powerball3.stl"/>
        </geometry>
        <material name="grey">
    <color rgba="0.5 0.5 0.5 1"/>
        </material>
      </visual>
      <collision>
        <origin rpy="0 0 0" xyz="0 0 0"/>
        <geometry>
          <mesh filename="package://g_ball_description/meshes/lwa4p_robotnik/powerball3.stl"/>
        </geometry>
      </collision>
    </link>
    <joint name="arm_4_joint" type="revolute">
      <origin rpy="1.5708 3.14159 0" xyz="0 0 0"/>
      <parent link="arm_3_link"/>
      <child link="arm_4_link"/>
      <axis xyz="0 0 -1"/>
      <calibration rising="0"/>
      <dynamics damping="5"/>
      <!--limit effort="176" lower="-2.0943951" upper="2.0943951" velocity="2.0"/-->
      <limit effort="176" lower="-2.97" upper="2.97" velocity="2.0"/>
      <safety_controller k_position="20" k_velocity="25" soft_lower_limit="-2.0843951" soft_upper_limit="2.0843951"/>
    </joint>
    <link name="arm_4_link">
      <inertial>
        <origin rpy="0 0 0" xyz="0 0 0"/>
        <mass value="1.68311"/>
        <inertia ixx="0.03" ixy="0" ixz="0" iyy="0.03" iyz="0" izz="0.03"/>
      </inertial>
      <visual>
        <origin rpy="0 0 0" xyz="0 0 0"/>
        <geometry>
          <mesh filename="package://g_ball_description/meshes/lwa4p_robotnik/powerball4_robotnik.stl"/>
        </geometry>
      </visual>
      <collision>
        <origin rpy="0 0 0" xyz="0 0 0"/>
        <geometry>
          <mesh filename="package://g_ball_description/meshes/lwa4p_robotnik/powerball4_robotnik.stl"/>
        </geometry>
      </collision>
    </link>
    <joint name="arm_5_joint" type="revolute">
      <!--origin rpy="1.5708 0 0" xyz="0 0.005 -0.3049"/-->
      <origin rpy="1.5708 0 0" xyz="0 0.005 -0.365"/>
      <parent link="arm_4_link"/>
      <child link="arm_5_link"/>
      <axis xyz="0 0 -1"/>
      <calibration rising="0"/>
      <dynamics damping="5"/>
      <!--limit effort="41.6" lower="-6.2831853" upper="6.2831853" velocity="2.0"/-->
      <limit effort="41.6" lower="-2.44" upper="2.44" velocity="2.0"/>
      <safety_controller k_position="20" k_velocity="25" soft_lower_limit="-6.2731853" soft_upper_limit="6.2731853"/>
    </joint>
    <link name="arm_5_link">
      <inertial>
        <origin rpy="0 0 0" xyz="0 0 0"/>
        <mass value="0.807"/>
        <inertia ixx="0.03" ixy="0" ixz="0" iyy="0.03" iyz="0" izz="0.03"/>
      </inertial>
      <visual>
        <origin rpy="0 0 0" xyz="0 0 0"/>
        <geometry>
          <mesh filename="package://g_ball_description/meshes/lwa4p_robotnik/powerball5.stl"/>
        </geometry>
      </visual>
      <material name="grey">
    <color rgba="0.5 0.5 0.5 1"/>
      </material>
      <collision>
        <origin rpy="0 0 0" xyz="0 0 0"/>
        <geometry>
          <mesh filename="package://g_ball_description/meshes/lwa4p_robotnik/powerball5.stl"/>
        </geometry>
      </collision>
    </link>
    <joint name="arm_6_joint" type="revolute">
      <origin rpy="-1.5708 0 0" xyz="0 0 0"/>
      <parent link="arm_5_link"/>
      <child link="arm_6_link"/>
      <axis xyz="0 0 -1"/>
      <calibration rising="0"/>
      <dynamics damping="5"/>
      <!--limit effort="20.1" lower="-2.0943951" upper="2.0943951" velocity="2.0"/-->
      <limit effort="20.1" lower="-2.97" upper="2.97" velocity="2.0"/>
      <safety_controller k_position="20" k_velocity="25" soft_lower_limit="-2.0843951" soft_upper_limit="2.0843951"/>
    </joint>
    <link name="arm_6_link">
      <inertial>
        <origin rpy="0 0 0" xyz="0 0 0"/>
        <mass value="0.819"/>
        <inertia ixx="0.01" ixy="0" ixz="0" iyy="0.01" iyz="0" izz="0.01"/>
      </inertial>
      <visual>
        <origin rpy="0 0 0" xyz="0 0 0"/>
        <geometry>
          <mesh filename="package://g_ball_description/meshes/lwa4p_robotnik/powerball6.stl"/>
        </geometry>
      </visual>
      <collision>
        <origin rpy="0 0 0" xyz="0 0 0"/>
        <geometry>
          <mesh filename="package://g_ball_description/meshes/lwa4p_robotnik/powerball6.stl"/>
        </geometry>
      </collision>
    </link>
    <gazebo reference="arm_0_link">
      <material value="PR2/Grey"/>
      <turnGravityOff>false</turnGravityOff>
      <selfCollide>true</selfCollide>
    </gazebo>
    <gazebo reference="arm_1_link">
      <material value="PR2/Blue"/>
      <turnGravityOff>false</turnGravityOff>
      <selfCollide>true</selfCollide>
    </gazebo>
    <gazebo reference="arm_2_link">
      <material value="PR2/Grey"/>
      <turnGravityOff>false</turnGravityOff>
      <selfCollide>true</selfCollide>
    </gazebo>
    <gazebo reference="arm_3_link">
      <material value="PR2/Blue"/>
      <turnGravityOff>false</turnGravityOff>
      <selfCollide>true</selfCollide>
    </gazebo>
    <gazebo reference="arm_4_link">
      <material value="PR2/Grey"/>
      <turnGravityOff>false</turnGravityOff>
      <selfCollide>true</selfCollide>
    </gazebo>
    <gazebo reference="arm_5_link">
      <material value="PR2/Blue"/>
      <turnGravityOff>false</turnGravityOff>
      <selfCollide>true</selfCollide>
    </gazebo>
    <gazebo reference="arm_6_link">
      <material value="PR2/Grey"/>
      <turnGravityOff>false</turnGravityOff>
      <selfCollide>true</selfCollide>
    </gazebo>
    <transmission name="arm_1_trans" type="pr2_mechanism_model/SimpleTransmission">
      <actuator name="arm_1_motor"/>
      <joint name="arm_1_joint"/>
      <mechanicalReduction>1</mechanicalReduction>
    </transmission>
    <transmission name="arm_2_trans" type="pr2_mechanism_model/SimpleTransmission">
      <actuator name="arm_2_motor"/>
      <joint name="arm_2_joint"/>
      <mechanicalReduction>1</mechanicalReduction>
    </transmission>
    <transmission name="arm_3_trans" type="pr2_mechanism_model/SimpleTransmission">
      <actuator name="arm_3_motor"/>
      <joint name="arm_3_joint"/>
      <mechanicalReduction>1</mechanicalReduction>
    </transmission>
    <transmission name="arm_4_trans" type="pr2_mechanism_model/SimpleTransmission">
      <actuator name="arm_4_motor"/>
      <joint name="arm_4_joint"/>
      <mechanicalReduction>1</mechanicalReduction>
    </transmission>
    <transmission name="arm_5_trans" type="pr2_mechanism_model/SimpleTransmission">
      <actuator name="arm_5_motor"/>
      <joint name="arm_5_joint"/>
      <mechanicalReduction>1</mechanicalReduction>
    </transmission>
    <transmission name="arm_6_trans" type="pr2_mechanism_model/SimpleTransmission">
      <actuator name="arm_6_motor"/>
      <joint name="arm_6_joint"/>
      <mechanicalReduction>1</mechanicalReduction>
    </transmission>

  </xacro:macro>

</robot>

